2019-08-22 17:51:56 default[20190822t104953]  "GET / HTTP/1.1" 502
2019-08-22 17:51:59 default[20190822t104953]  [2019-08-22 17:51:59 +0000] [7] [INFO] Starting gunicorn 19.9.0
2019-08-22 17:51:59 default[20190822t104953]  [2019-08-22 17:51:59 +0000] [7] [INFO] Listening at: http://0.0.0.0:8081 (7)
2019-08-22 17:51:59 default[20190822t104953]  [2019-08-22 17:51:59 +0000] [7] [INFO] Using worker: threads
2019-08-22 17:51:59 default[20190822t104953]  [2019-08-22 17:51:59 +0000] [18] [INFO] Booting worker with pid: 18
2019-08-22 17:51:59 default[20190822t104953]  [2019-08-22 17:51:59 +0000] [18] [ERROR] Exception in worker process
2019-08-22 17:51:59 default[20190822t104953]  Traceback (most recent call last):    File "/env/lib/python3.7/site-packages/gunicorn/arbiter.py", line 583, in spawn_worker      worker.init_process()    File "/env/lib/python3.7/site-packages/gunicorn/workers/gthread.py", line 104, in init_process      super(ThreadWorker, self).init_process()    File "/env/lib/python3.7/site-packages/gunicorn/workers/base.py", line 129, in init_process      self.load_wsgi()    File "/env/lib/python3.7/site-packages/gunicorn/workers/base.py", line 138, in load_wsgi      self.wsgi = self.app.wsgi()    File "/env/lib/python3.7/site-packages/gunicorn/app/base.py", line 67, in wsgi      self.callable = self.load()    File "/env/lib/python3.7/site-packages/gunicorn/app/wsgiapp.py", line 52, in load      return self.load_wsgiapp()    File "/env/lib/python3.7/site-packages/gunicorn/app/wsgiapp.py", line 41, in load_wsgiapp      return util.import_app(self.app_uri)    File "/env/lib/python3.7/site-packages/gunicorn/util.py", line 350, in import_app      __import__(module)  ModuleNotFoundError: No module named 'main'
2019-08-22 17:51:59 default[20190822t104953]  [2019-08-22 17:51:59 +0000] [18] [INFO] Worker exiting (pid: 18)
2019-08-22 17:51:59 default[20190822t104953]  [2019-08-22 17:51:59 +0000] [22] [INFO] Booting worker with pid: 22
2019-08-22 17:51:59 default[20190822t104953]  [2019-08-22 17:51:59 +0000] [22] [ERROR] Exception in worker process
2019-08-22 17:51:59 default[20190822t104953]  Traceback (most recent call last):    File "/env/lib/python3.7/site-packages/gunicorn/arbiter.py", line 583, in spawn_worker      worker.init_process()    File "/env/lib/python3.7/site-packages/gunicorn/workers/gthread.py", line 104, in init_process      super(ThreadWorker, self).init_process()    File "/env/lib/python3.7/site-packages/gunicorn/workers/base.py", line 129, in init_process      self.load_wsgi()    File "/env/lib/python3.7/site-packages/gunicorn/workers/base.py", line 138, in load_wsgi      self.wsgi = self.app.wsgi()    File "/env/lib/python3.7/site-packages/gunicorn/app/base.py", line 67, in wsgi      self.callable = self.load()    File "/env/lib/python3.7/site-packages/gunicorn/app/wsgiapp.py", line 52, in load      return self.load_wsgiapp()    File "/env/lib/python3.7/site-packages/gunicorn/app/wsgiapp.py", line 41, in load_wsgiapp      return util.import_app(self.app_uri)    File "/env/lib/python3.7/site-packages/gunicorn/util.py", line 350, in import_app      __import__(module)  ModuleNotFoundError: No module named 'main'
2019-08-22 17:51:59 default[20190822t104953]  [2019-08-22 17:51:59 +0000] [22] [INFO] Worker exiting (pid: 22)
2019-08-22 17:51:59 default[20190822t104953]  Traceback (most recent call last):    File "/env/lib/python3.7/site-packages/gunicorn/arbiter.py", line 203, in run      self.manage_workers()    File "/env/lib/python3.7/site-packages/gunicorn/arbiter.py", line 545, in manage_workers      self.spawn_workers()    File "/env/lib/python3.7/site-packages/gunicorn/arbiter.py", line 617, in spawn_workers      time.sleep(0.1 * random.random())    File "/env/lib/python3.7/site-packages/gunicorn/arbiter.py", line 245, in handle_chld      self.reap_workers()    File "/env/lib/python3.7/site-packages/gunicorn/arbiter.py", line 525, in reap_workers      raise HaltServer(reason, self.WORKER_BOOT_ERROR)  gunicorn.errors.HaltServer: <HaltServer 'Worker failed to boot.' 3>
2019-08-22 17:51:59 default[20190822t104953]
2019-08-22 17:51:59 default[20190822t104953]  During handling of the above exception, another exception occurred:
2019-08-22 17:51:59 default[20190822t104953]
2019-08-22 17:51:59 default[20190822t104953]  Traceback (most recent call last):    File "/env/bin/gunicorn", line 10, in <module>      sys.exit(run())    File "/env/lib/python3.7/site-packages/gunicorn/app/wsgiapp.py", line 61, in run      WSGIApplication("%(prog)s [OPTIONS] [APP_MODULE]").run()    File "/env/lib/python3.7/site-packages/gunicorn/app/base.py", line 223, in run      super(Application, self).run()    File "/env/lib/python3.7/site-packages/gunicorn/app/base.py", line 72, in run      Arbiter(self).run()    File "/env/lib/python3.7/site-packages/gunicorn/arbiter.py", line 232, in run      self.halt(reason=inst.reason, exit_status=inst.exit_status)    File "/env/lib/python3.7/site-packages/gunicorn/arbiter.py", line 345, in halt      self.stop()    File "/env/lib/python3.7/site-packages/gunicorn/arbiter.py", line 393, in stop      time.sleep(0.1)    File "/env/lib/python3.7/site-packages/gunicorn/arbiter.py", line 245, in handle_chld      self.reap_workers()    File "/env/lib/python3.7/site-packages/gunicorn/arbiter.py", line 525, in reap_workers      raise HaltServer(reason, self.WORKER_BOOT_ERROR)  gunicorn.errors.HaltServer: <HaltServer 'Worker failed to boot.' 3>
2019-08-22 17:52:00 default[20190822t104953]  "GET /favicon.ico HTTP/1.1" 502
2019-08-22 17:52:02 default[20190822t104953]  [2019-08-22 17:52:02 +0000] [8] [INFO] Starting gunicorn 19.9.0
2019-08-22 17:52:02 default[20190822t104953]  [2019-08-22 17:52:02 +0000] [8] [INFO] Listening at: http://0.0.0.0:8081 (8)
2019-08-22 17:52:02 default[20190822t104953]  [2019-08-22 17:52:02 +0000] [8] [INFO] Using worker: threads
2019-08-22 17:52:02 default[20190822t104953]  [2019-08-22 17:52:02 +0000] [19] [INFO] Booting worker with pid: 19
2019-08-22 17:52:02 default[20190822t104953]  [2019-08-22 17:52:02 +0000] [19] [ERROR] Exception in worker process
2019-08-22 17:52:02 default[20190822t104953]  Traceback (most recent call last):    File "/env/lib/python3.7/site-packages/gunicorn/arbiter.py", line 583, in spawn_worker      worker.init_process()    File "/env/lib/python3.7/site-packages/gunicorn/workers/gthread.py", line 104, in init_process      super(ThreadWorker, self).init_process()    File "/env/lib/python3.7/site-packages/gunicorn/workers/base.py", line 129, in init_process      self.load_wsgi()    File "/env/lib/python3.7/site-packages/gunicorn/workers/base.py", line 138, in load_wsgi      self.wsgi = self.app.wsgi()    File "/env/lib/python3.7/site-packages/gunicorn/app/base.py", line 67, in wsgi      self.callable = self.load()    File "/env/lib/python3.7/site-packages/gunicorn/app/wsgiapp.py", line 52, in load      return self.load_wsgiapp()    File "/env/lib/python3.7/site-packages/gunicorn/app/wsgiapp.py", line 41, in load_wsgiapp      return util.import_app(self.app_uri)    File "/env/lib/python3.7/site-packages/gunicorn/util.py", line 350, in import_app      __import__(module)  ModuleNotFoundError: No module named 'main'
2019-08-22 17:52:02 default[20190822t104953]  [2019-08-22 17:52:02 +0000] [19] [INFO] Worker exiting (pid: 19)
2019-08-22 17:52:02 default[20190822t104953]  [2019-08-22 17:52:02 +0000] [22] [INFO] Booting worker with pid: 22
2019-08-22 17:52:02 default[20190822t104953]  [2019-08-22 17:52:02 +0000] [22] [ERROR] Exception in worker process
2019-08-22 17:52:02 default[20190822t104953]  Traceback (most recent call last):    File "/env/lib/python3.7/site-packages/gunicorn/arbiter.py", line 583, in spawn_worker      worker.init_process()    File "/env/lib/python3.7/site-packages/gunicorn/workers/gthread.py", line 104, in init_process      super(ThreadWorker, self).init_process()    File "/env/lib/python3.7/site-packages/gunicorn/workers/base.py", line 129, in init_process      self.load_wsgi()    File "/env/lib/python3.7/site-packages/gunicorn/workers/base.py", line 138, in load_wsgi      self.wsgi = self.app.wsgi()    File "/env/lib/python3.7/site-packages/gunicorn/app/base.py", line 67, in wsgi      self.callable = self.load()    File "/env/lib/python3.7/site-packages/gunicorn/app/wsgiapp.py", line 52, in load      return self.load_wsgiapp()    File "/env/lib/python3.7/site-packages/gunicorn/app/wsgiapp.py", line 41, in load_wsgiapp      return util.import_app(self.app_uri)    File "/env/lib/python3.7/site-packages/gunicorn/util.py", line 350, in import_app      __import__(module)  ModuleNotFoundError: No module named 'main'
2019-08-22 17:52:02 default[20190822t104953]  [2019-08-22 17:52:02 +0000] [22] [INFO] Worker exiting (pid: 22)
2019-08-22 17:52:03 default[20190822t104953]  [2019-08-22 17:52:03 +0000] [8] [INFO] Shutting down: Master
2019-08-22 17:52:03 default[20190822t104953]  [2019-08-22 17:52:03 +0000] [8] [INFO] Reason: Worker failed to boot.
2019-08-22 17:52:15 default[20190822t104953]  "GET /get-location.html HTTP/1.1" 502
2019-08-22 17:52:17 default[20190822t104953]  [2019-08-22 17:52:17 +0000] [8] [INFO] Starting gunicorn 19.9.0
2019-08-22 17:52:17 default[20190822t104953]  [2019-08-22 17:52:17 +0000] [8] [INFO] Listening at: http://0.0.0.0:8081 (8)
2019-08-22 17:52:17 default[20190822t104953]  [2019-08-22 17:52:17 +0000] [8] [INFO] Using worker: threads
2019-08-22 17:52:17 default[20190822t104953]  [2019-08-22 17:52:17 +0000] [19] [INFO] Booting worker with pid: 19
2019-08-22 17:52:17 default[20190822t104953]  [2019-08-22 17:52:17 +0000] [19] [ERROR] Exception in worker process
2019-08-22 17:52:17 default[20190822t104953]  Traceback (most recent call last):    File "/env/lib/python3.7/site-packages/gunicorn/arbiter.py", line 583, in spawn_worker      worker.init_process()    File "/env/lib/python3.7/site-packages/gunicorn/workers/gthread.py", line 104, in init_process      super(ThreadWorker, self).init_process()    File "/env/lib/python3.7/site-packages/gunicorn/workers/base.py", line 129, in init_process      self.load_wsgi()    File "/env/lib/python3.7/site-packages/gunicorn/workers/base.py", line 138, in load_wsgi      self.wsgi = self.app.wsgi()    File "/env/lib/python3.7/site-packages/gunicorn/app/base.py", line 67, in wsgi      self.callable = self.load()    File "/env/lib/python3.7/site-packages/gunicorn/app/wsgiapp.py", line 52, in load      return self.load_wsgiapp()    File "/env/lib/python3.7/site-packages/gunicorn/app/wsgiapp.py", line 41, in load_wsgiapp      return util.import_app(self.app_uri)    File "/env/lib/python3.7/site-packages/gunicorn/util.py", line 350, in import_app      __import__(module)  ModuleNotFoundError: No module named 'main'
2019-08-22 17:52:17 default[20190822t104953]  [2019-08-22 17:52:17 +0000] [19] [INFO] Worker exiting (pid: 19)
2019-08-22 17:52:17 default[20190822t104953]  Exception ignored in: <function _after_at_fork_weak_calls at 0x159d7bbd9400>
2019-08-22 17:52:17 default[20190822t104953]  Traceback (most recent call last):    File "/opt/python3.7/lib/python3.7/logging/__init__.py", line 269, in _after_at_fork_weak_calls      _at_fork_weak_calls('release')    File "/opt/python3.7/lib/python3.7/logging/__init__.py", line 254, in _at_fork_weak_calls      for instance in _at_fork_acquire_release_weakset:    File "/opt/python3.7/lib/python3.7/_weakrefset.py", line 59, in __iter__  [2019-08-22 17:52:17 +0000] [22] [INFO] Booting worker with pid: 22
2019-08-22 17:52:17 default[20190822t104953]      with _IterationGuard(self):
2019-08-22 17:52:17 default[20190822t104953]    File "/opt/python3.7/lib/python3.7/_weakrefset.py", line 18, in __init__
2019-08-22 17:52:17 default[20190822t104953]      self.weakcontainer = ref(weakcontainer)
2019-08-22 17:52:17 default[20190822t104953]    File "/env/lib/python3.7/site-packages/gunicorn/arbiter.py", line 245, in handle_chld
2019-08-22 17:52:17 default[20190822t104953]      self.reap_workers()
2019-08-22 17:52:17 default[20190822t104953]    File "/env/lib/python3.7/site-packages/gunicorn/arbiter.py", line 525, in reap_workers
2019-08-22 17:52:17 default[20190822t104953]      raise HaltServer(reason, self.WORKER_BOOT_ERROR)
2019-08-22 17:52:17 default[20190822t104953]  gunicorn.errors.HaltServer: <HaltServer 'Worker failed to boot.' 3>
2019-08-22 17:52:17 default[20190822t104953]  [2019-08-22 17:52:17 +0000] [22] [ERROR] Exception in worker process
2019-08-22 17:52:17 default[20190822t104953]  Traceback (most recent call last):    File "/env/lib/python3.7/site-packages/gunicorn/arbiter.py", line 583, in spawn_worker      worker.init_process()    File "/env/lib/python3.7/site-packages/gunicorn/workers/gthread.py", line 104, in init_process      super(ThreadWorker, self).init_process()    File "/env/lib/python3.7/site-packages/gunicorn/workers/base.py", line 129, in init_process      self.load_wsgi()    File "/env/lib/python3.7/site-packages/gunicorn/workers/base.py", line 138, in load_wsgi      self.wsgi = self.app.wsgi()    File "/env/lib/python3.7/site-packages/gunicorn/app/base.py", line 67, in wsgi      self.callable = self.load()    File "/env/lib/python3.7/site-packages/gunicorn/app/wsgiapp.py", line 52, in load      return self.load_wsgiapp()    File "/env/lib/python3.7/site-packages/gunicorn/app/wsgiapp.py", line 41, in load_wsgiapp      return util.import_app(self.app_uri)    File "/env/lib/python3.7/site-packages/gunicorn/util.py", line 350, in import_app      __import__(module)  ModuleNotFoundError: No module named 'main'
2019-08-22 17:52:17 default[20190822t104953]  [2019-08-22 17:52:17 +0000] [22] [INFO] Worker exiting (pid: 22)
2019-08-22 17:52:17 default[20190822t104953]  [2019-08-22 17:52:17 +0000] [8] [INFO] Shutting down: Master
2019-08-22 17:52:17 default[20190822t104953]  [2019-08-22 17:52:17 +0000] [8] [INFO] Reason: Worker failed to boot.
2019-08-22 17:52:18 default[20190822t104953]  "GET /favicon.ico HTTP/1.1" 502
2019-08-22 17:52:20 default[20190822t104953]  [2019-08-22 17:52:20 +0000] [8] [INFO] Starting gunicorn 19.9.0
2019-08-22 17:52:20 default[20190822t104953]  [2019-08-22 17:52:20 +0000] [8] [INFO] Listening at: http://0.0.0.0:8081 (8)
2019-08-22 17:52:20 default[20190822t104953]  [2019-08-22 17:52:20 +0000] [8] [INFO] Using worker: threads
2019-08-22 17:52:20 default[20190822t104953]  [2019-08-22 17:52:20 +0000] [20] [INFO] Booting worker with pid: 20
2019-08-22 17:52:20 default[20190822t104953]  [2019-08-22 17:52:20 +0000] [20] [ERROR] Exception in worker process
2019-08-22 17:52:20 default[20190822t104953]  Traceback (most recent call last):    File "/env/lib/python3.7/site-packages/gunicorn/arbiter.py", line 583, in spawn_worker      worker.init_process()    File "/env/lib/python3.7/site-packages/gunicorn/workers/gthread.py", line 104, in init_process      super(ThreadWorker, self).init_process()    File "/env/lib/python3.7/site-packages/gunicorn/workers/base.py", line 129, in init_process      self.load_wsgi()    File "/env/lib/python3.7/site-packages/gunicorn/workers/base.py", line 138, in load_wsgi      self.wsgi = self.app.wsgi()    File "/env/lib/python3.7/site-packages/gunicorn/app/base.py", line 67, in wsgi      self.callable = self.load()    File "/env/lib/python3.7/site-packages/gunicorn/app/wsgiapp.py", line 52, in load      return self.load_wsgiapp()    File "/env/lib/python3.7/site-packages/gunicorn/app/wsgiapp.py", line 41, in load_wsgiapp      return util.import_app(self.app_uri)    File "/env/lib/python3.7/site-packages/gunicorn/util.py", line 350, in import_app      __import__(module)  ModuleNotFoundError: No module named 'main'
2019-08-22 17:52:20 default[20190822t104953]  [2019-08-22 17:52:20 +0000] [20] [INFO] Worker exiting (pid: 20)
2019-08-22 17:52:20 default[20190822t104953]  [2019-08-22 17:52:20 +0000] [23] [INFO] Booting worker with pid: 23
2019-08-22 17:52:20 default[20190822t104953]  [2019-08-22 17:52:20 +0000] [23] [ERROR] Exception in worker process
2019-08-22 17:52:20 default[20190822t104953]  Traceback (most recent call last):    File "/env/lib/python3.7/site-packages/gunicorn/arbiter.py", line 583, in spawn_worker      worker.init_process()    File "/env/lib/python3.7/site-packages/gunicorn/workers/gthread.py", line 104, in init_process      super(ThreadWorker, self).init_process()    File "/env/lib/python3.7/site-packages/gunicorn/workers/base.py", line 129, in init_process      self.load_wsgi()    File "/env/lib/python3.7/site-packages/gunicorn/workers/base.py", line 138, in load_wsgi      self.wsgi = self.app.wsgi()    File "/env/lib/python3.7/site-packages/gunicorn/app/base.py", line 67, in wsgi      self.callable = self.load()    File "/env/lib/python3.7/site-packages/gunicorn/app/wsgiapp.py", line 52, in load      return self.load_wsgiapp()    File "/env/lib/python3.7/site-packages/gunicorn/app/wsgiapp.py", line 41, in load_wsgiapp      return util.import_app(self.app_uri)    File "/env/lib/python3.7/site-packages/gunicorn/util.py", line 350, in import_app      __import__(module)  ModuleNotFoundError: No module named 'main'
2019-08-22 17:52:20 default[20190822t104953]  [2019-08-22 17:52:20 +0000] [23] [INFO] Worker exiting (pid: 23)
2019-08-22 17:52:20 default[20190822t104953]  [2019-08-22 17:52:20 +0000] [8] [INFO] Shutting down: Master
2019-08-22 17:52:20 default[20190822t104953]  [2019-08-22 17:52:20 +0000] [8] [INFO] Reason: Worker failed to boot.
